[2025-08-13T02:13:07.539+0000] {local_task_job_runner.py:120} INFO - ::group::Pre task execution logs
[2025-08-13T02:13:07.639+0000] {taskinstance.py:2076} INFO - Dependencies all met for dep_context=non-requeueable deps ti=<TaskInstance: playstore_review_etl_pipeline.extract_raw_reviews scheduled__2025-08-12T00:00:00+00:00 [queued]>
[2025-08-13T02:13:07.666+0000] {taskinstance.py:2076} INFO - Dependencies all met for dep_context=requeueable deps ti=<TaskInstance: playstore_review_etl_pipeline.extract_raw_reviews scheduled__2025-08-12T00:00:00+00:00 [queued]>
[2025-08-13T02:13:07.671+0000] {taskinstance.py:2306} INFO - Starting attempt 3 of 3
[2025-08-13T02:13:07.714+0000] {taskinstance.py:2330} INFO - Executing <Task(PythonOperator): extract_raw_reviews> on 2025-08-12 00:00:00+00:00
[2025-08-13T02:13:07.745+0000] {logging_mixin.py:188} WARNING - /home/***/.local/lib/python3.12/site-packages/***/task/task_runner/standard_task_runner.py:61 DeprecationWarning: This process (pid=274) is multi-threaded, use of fork() may lead to deadlocks in the child.
[2025-08-13T02:13:07.738+0000] {standard_task_runner.py:90} INFO - Running: ['***', 'tasks', 'run', 'playstore_review_etl_pipeline', 'extract_raw_reviews', 'scheduled__2025-08-12T00:00:00+00:00', '--job-id', '57', '--raw', '--subdir', 'DAGS_FOLDER/my_pipeline.py', '--cfg-path', '/tmp/tmpgumumtiv']
[2025-08-13T02:13:07.748+0000] {standard_task_runner.py:63} INFO - Started process 276 to run task
[2025-08-13T02:13:07.748+0000] {standard_task_runner.py:91} INFO - Job 57: Subtask extract_raw_reviews
[2025-08-13T02:13:07.856+0000] {task_command.py:426} INFO - Running <TaskInstance: playstore_review_etl_pipeline.extract_raw_reviews scheduled__2025-08-12T00:00:00+00:00 [running]> on host 30f90b9829ae
[2025-08-13T02:13:08.108+0000] {taskinstance.py:2648} INFO - Exporting env vars: AIRFLOW_CTX_DAG_EMAIL='your_email@domain.com' AIRFLOW_CTX_DAG_OWNER='data_engineering_team' AIRFLOW_CTX_DAG_ID='playstore_review_etl_pipeline' AIRFLOW_CTX_TASK_ID='extract_raw_reviews' AIRFLOW_CTX_EXECUTION_DATE='2025-08-12T00:00:00+00:00' AIRFLOW_CTX_TRY_NUMBER='3' AIRFLOW_CTX_DAG_RUN_ID='scheduled__2025-08-12T00:00:00+00:00'
[2025-08-13T02:13:08.111+0000] {taskinstance.py:430} INFO - ::endgroup::
[2025-08-13T02:13:08.141+0000] {my_pipeline.py:41} INFO - Starting Scraper Task...
[2025-08-13T02:13:08.143+0000] {my_pipeline.py:46} INFO - Calling scraper.main()...
[2025-08-13T02:13:08.145+0000] {scraper.py:172} INFO - === Google Play Store Review Scraper (SQLite) Started ===
[2025-08-13T02:13:08.146+0000] {scraper.py:34} ERROR - Error connecting to database: unable to open database file
[2025-08-13T02:13:08.148+0000] {scraper.py:199} ERROR - === Scraper Run Failed! Error: unable to open database file ===
Traceback (most recent call last):
  File "/opt/airflow/scraper_code/scraper.py", line 177, in main
    conn = get_db_connection()
           ^^^^^^^^^^^^^^^^^^^
  File "/opt/airflow/scraper_code/scraper.py", line 28, in get_db_connection
    conn = sqlite3.connect(DB_PATH)
           ^^^^^^^^^^^^^^^^^^^^^^^^
sqlite3.OperationalError: unable to open database file
[2025-08-13T02:13:08.161+0000] {my_pipeline.py:54} ERROR - Scraper task failed with exception: unable to open database file
Traceback (most recent call last):
  File "/opt/airflow/dags/my_pipeline.py", line 47, in run_scraper
    scraper_module.main()
  File "/opt/airflow/scraper_code/scraper.py", line 177, in main
    conn = get_db_connection()
           ^^^^^^^^^^^^^^^^^^^
  File "/opt/airflow/scraper_code/scraper.py", line 28, in get_db_connection
    conn = sqlite3.connect(DB_PATH)
           ^^^^^^^^^^^^^^^^^^^^^^^^
sqlite3.OperationalError: unable to open database file
[2025-08-13T02:13:08.173+0000] {taskinstance.py:441} INFO - ::group::Post task execution logs
[2025-08-13T02:13:08.174+0000] {taskinstance.py:2905} ERROR - Task failed with exception
Traceback (most recent call last):
  File "/home/airflow/.local/lib/python3.12/site-packages/airflow/models/taskinstance.py", line 465, in _execute_task
    result = _execute_callable(context=context, **execute_callable_kwargs)
             ^^^^^^^^^^^^^^^^^^^^^^^^^^^^^^^^^^^^^^^^^^^^^^^^^^^^^^^^^^^^^
  File "/home/airflow/.local/lib/python3.12/site-packages/airflow/models/taskinstance.py", line 432, in _execute_callable
    return execute_callable(context=context, **execute_callable_kwargs)
           ^^^^^^^^^^^^^^^^^^^^^^^^^^^^^^^^^^^^^^^^^^^^^^^^^^^^^^^^^^^^
  File "/home/airflow/.local/lib/python3.12/site-packages/airflow/models/baseoperator.py", line 400, in wrapper
    return func(self, *args, **kwargs)
           ^^^^^^^^^^^^^^^^^^^^^^^^^^^
  File "/home/airflow/.local/lib/python3.12/site-packages/airflow/operators/python.py", line 235, in execute
    return_value = self.execute_callable()
                   ^^^^^^^^^^^^^^^^^^^^^^^
  File "/home/airflow/.local/lib/python3.12/site-packages/airflow/operators/python.py", line 252, in execute_callable
    return self.python_callable(*self.op_args, **self.op_kwargs)
           ^^^^^^^^^^^^^^^^^^^^^^^^^^^^^^^^^^^^^^^^^^^^^^^^^^^^^
  File "/opt/airflow/dags/my_pipeline.py", line 47, in run_scraper
    scraper_module.main()
  File "/opt/airflow/scraper_code/scraper.py", line 177, in main
    conn = get_db_connection()
           ^^^^^^^^^^^^^^^^^^^
  File "/opt/airflow/scraper_code/scraper.py", line 28, in get_db_connection
    conn = sqlite3.connect(DB_PATH)
           ^^^^^^^^^^^^^^^^^^^^^^^^
sqlite3.OperationalError: unable to open database file
[2025-08-13T02:13:08.201+0000] {taskinstance.py:1206} INFO - Marking task as FAILED. dag_id=playstore_review_etl_pipeline, task_id=extract_raw_reviews, run_id=scheduled__2025-08-12T00:00:00+00:00, execution_date=20250812T000000, start_date=20250813T021307, end_date=20250813T021308
[2025-08-13T02:13:08.239+0000] {logging_mixin.py:188} WARNING - /home/***/.local/lib/python3.12/site-packages/***/utils/email.py:154 RemovedInAirflow3Warning: Fetching SMTP credentials from configuration variables will be deprecated in a future release. Please set credentials using a connection instead.
[2025-08-13T02:13:08.241+0000] {configuration.py:1050} WARNING - section/key [smtp/smtp_user] not found in config
[2025-08-13T02:13:08.242+0000] {email.py:271} INFO - Email alerting: attempt 1
[2025-08-13T02:13:08.261+0000] {configuration.py:1050} WARNING - section/key [smtp/smtp_user] not found in config
[2025-08-13T02:13:08.262+0000] {email.py:271} INFO - Email alerting: attempt 1
[2025-08-13T02:13:08.265+0000] {taskinstance.py:879} ERROR - Failed to send email to: ['your_email@domain.com']
Traceback (most recent call last):
  File "/home/airflow/.local/lib/python3.12/site-packages/airflow/models/taskinstance.py", line 2479, in _run_raw_task
    self._execute_task_with_callbacks(context, test_mode, session=session)
  File "/home/airflow/.local/lib/python3.12/site-packages/airflow/models/taskinstance.py", line 2676, in _execute_task_with_callbacks
    result = self._execute_task(context, task_orig)
             ^^^^^^^^^^^^^^^^^^^^^^^^^^^^^^^^^^^^^^
  File "/home/airflow/.local/lib/python3.12/site-packages/airflow/models/taskinstance.py", line 2701, in _execute_task
    return _execute_task(self, context, task_orig)
           ^^^^^^^^^^^^^^^^^^^^^^^^^^^^^^^^^^^^^^^
  File "/home/airflow/.local/lib/python3.12/site-packages/airflow/models/taskinstance.py", line 465, in _execute_task
    result = _execute_callable(context=context, **execute_callable_kwargs)
             ^^^^^^^^^^^^^^^^^^^^^^^^^^^^^^^^^^^^^^^^^^^^^^^^^^^^^^^^^^^^^
  File "/home/airflow/.local/lib/python3.12/site-packages/airflow/models/taskinstance.py", line 432, in _execute_callable
    return execute_callable(context=context, **execute_callable_kwargs)
           ^^^^^^^^^^^^^^^^^^^^^^^^^^^^^^^^^^^^^^^^^^^^^^^^^^^^^^^^^^^^
  File "/home/airflow/.local/lib/python3.12/site-packages/airflow/models/baseoperator.py", line 400, in wrapper
    return func(self, *args, **kwargs)
           ^^^^^^^^^^^^^^^^^^^^^^^^^^^
  File "/home/airflow/.local/lib/python3.12/site-packages/airflow/operators/python.py", line 235, in execute
    return_value = self.execute_callable()
                   ^^^^^^^^^^^^^^^^^^^^^^^
  File "/home/airflow/.local/lib/python3.12/site-packages/airflow/operators/python.py", line 252, in execute_callable
    return self.python_callable(*self.op_args, **self.op_kwargs)
           ^^^^^^^^^^^^^^^^^^^^^^^^^^^^^^^^^^^^^^^^^^^^^^^^^^^^^
  File "/opt/airflow/dags/my_pipeline.py", line 47, in run_scraper
    scraper_module.main()
  File "/opt/airflow/scraper_code/scraper.py", line 177, in main
    conn = get_db_connection()
           ^^^^^^^^^^^^^^^^^^^
  File "/opt/airflow/scraper_code/scraper.py", line 28, in get_db_connection
    conn = sqlite3.connect(DB_PATH)
           ^^^^^^^^^^^^^^^^^^^^^^^^
sqlite3.OperationalError: unable to open database file

During handling of the above exception, another exception occurred:

Traceback (most recent call last):
  File "/home/airflow/.local/lib/python3.12/site-packages/airflow/models/taskinstance.py", line 1063, in _email_alert
    send_email(task.email, subject, html_content)
  File "/home/airflow/.local/lib/python3.12/site-packages/airflow/utils/email.py", line 80, in send_email
    return backend(
           ^^^^^^^^
  File "/home/airflow/.local/lib/python3.12/site-packages/airflow/utils/email.py", line 154, in send_email_smtp
    send_mime_email(e_from=mail_from, e_to=recipients, mime_msg=msg, conn_id=conn_id, dryrun=dryrun)
  File "/home/airflow/.local/lib/python3.12/site-packages/airflow/utils/email.py", line 273, in send_mime_email
    smtp_conn = _get_smtp_connection(smtp_host, smtp_port, smtp_timeout, smtp_ssl)
                ^^^^^^^^^^^^^^^^^^^^^^^^^^^^^^^^^^^^^^^^^^^^^^^^^^^^^^^^^^^^^^^^^^
  File "/home/airflow/.local/lib/python3.12/site-packages/airflow/utils/email.py", line 317, in _get_smtp_connection
    return smtplib.SMTP(host=host, port=port, timeout=timeout)
           ^^^^^^^^^^^^^^^^^^^^^^^^^^^^^^^^^^^^^^^^^^^^^^^^^^^
  File "/usr/local/lib/python3.12/smtplib.py", line 255, in __init__
    (code, msg) = self.connect(host, port)
                  ^^^^^^^^^^^^^^^^^^^^^^^^
  File "/usr/local/lib/python3.12/smtplib.py", line 341, in connect
    self.sock = self._get_socket(host, port, self.timeout)
                ^^^^^^^^^^^^^^^^^^^^^^^^^^^^^^^^^^^^^^^^^^
  File "/usr/local/lib/python3.12/smtplib.py", line 312, in _get_socket
    return socket.create_connection((host, port), timeout,
           ^^^^^^^^^^^^^^^^^^^^^^^^^^^^^^^^^^^^^^^^^^^^^^^
  File "/usr/local/lib/python3.12/socket.py", line 852, in create_connection
    raise exceptions[0]
  File "/usr/local/lib/python3.12/socket.py", line 837, in create_connection
    sock.connect(sa)
ConnectionRefusedError: [Errno 111] Connection refused

During handling of the above exception, another exception occurred:

Traceback (most recent call last):
  File "/home/airflow/.local/lib/python3.12/site-packages/airflow/models/taskinstance.py", line 877, in _handle_failure
    task_instance.email_alert(error, failure_context["task"])
  File "/home/airflow/.local/lib/python3.12/site-packages/airflow/models/taskinstance.py", line 3163, in email_alert
    _email_alert(task_instance=self, exception=exception, task=task)
  File "/home/airflow/.local/lib/python3.12/site-packages/airflow/models/taskinstance.py", line 1065, in _email_alert
    send_email(task.email, subject, html_content_err)
  File "/home/airflow/.local/lib/python3.12/site-packages/airflow/utils/email.py", line 80, in send_email
    return backend(
           ^^^^^^^^
  File "/home/airflow/.local/lib/python3.12/site-packages/airflow/utils/email.py", line 154, in send_email_smtp
    send_mime_email(e_from=mail_from, e_to=recipients, mime_msg=msg, conn_id=conn_id, dryrun=dryrun)
  File "/home/airflow/.local/lib/python3.12/site-packages/airflow/utils/email.py", line 273, in send_mime_email
    smtp_conn = _get_smtp_connection(smtp_host, smtp_port, smtp_timeout, smtp_ssl)
                ^^^^^^^^^^^^^^^^^^^^^^^^^^^^^^^^^^^^^^^^^^^^^^^^^^^^^^^^^^^^^^^^^^
  File "/home/airflow/.local/lib/python3.12/site-packages/airflow/utils/email.py", line 317, in _get_smtp_connection
    return smtplib.SMTP(host=host, port=port, timeout=timeout)
           ^^^^^^^^^^^^^^^^^^^^^^^^^^^^^^^^^^^^^^^^^^^^^^^^^^^
  File "/usr/local/lib/python3.12/smtplib.py", line 255, in __init__
    (code, msg) = self.connect(host, port)
                  ^^^^^^^^^^^^^^^^^^^^^^^^
  File "/usr/local/lib/python3.12/smtplib.py", line 341, in connect
    self.sock = self._get_socket(host, port, self.timeout)
                ^^^^^^^^^^^^^^^^^^^^^^^^^^^^^^^^^^^^^^^^^^
  File "/usr/local/lib/python3.12/smtplib.py", line 312, in _get_socket
    return socket.create_connection((host, port), timeout,
           ^^^^^^^^^^^^^^^^^^^^^^^^^^^^^^^^^^^^^^^^^^^^^^^
  File "/usr/local/lib/python3.12/socket.py", line 852, in create_connection
    raise exceptions[0]
  File "/usr/local/lib/python3.12/socket.py", line 837, in create_connection
    sock.connect(sa)
ConnectionRefusedError: [Errno 111] Connection refused
[2025-08-13T02:13:08.305+0000] {standard_task_runner.py:110} ERROR - Failed to execute job 57 for task extract_raw_reviews (unable to open database file; 276)
[2025-08-13T02:13:08.329+0000] {local_task_job_runner.py:240} INFO - Task exited with return code 1
[2025-08-13T02:13:08.375+0000] {taskinstance.py:3498} INFO - 0 downstream tasks scheduled from follow-on schedule check
[2025-08-13T02:13:08.390+0000] {local_task_job_runner.py:222} INFO - ::endgroup::
